2024-04-21 18:17:57 - ERROR - Exception on /edit_user/1 [GET]
Traceback (most recent call last):
  File "c:\Users\ellie\OneDrive\Documents\Programming\Python\Level 6\Major Project\.venv\Lib\site-packages\flask\app.py", line 1463, in wsgi_app
    response = self.full_dispatch_request()
               ^^^^^^^^^^^^^^^^^^^^^^^^^^^^
  File "c:\Users\ellie\OneDrive\Documents\Programming\Python\Level 6\Major Project\.venv\Lib\site-packages\flask\app.py", line 872, in full_dispatch_request
    rv = self.handle_user_exception(e)
         ^^^^^^^^^^^^^^^^^^^^^^^^^^^^^
  File "c:\Users\ellie\OneDrive\Documents\Programming\Python\Level 6\Major Project\.venv\Lib\site-packages\flask\app.py", line 870, in full_dispatch_request
    rv = self.dispatch_request()
         ^^^^^^^^^^^^^^^^^^^^^^^
  File "c:\Users\ellie\OneDrive\Documents\Programming\Python\Level 6\Major Project\.venv\Lib\site-packages\flask\app.py", line 855, in dispatch_request
    return self.ensure_sync(self.view_functions[rule.endpoint])(**view_args)  # type: ignore[no-any-return]
           ^^^^^^^^^^^^^^^^^^^^^^^^^^^^^^^^^^^^^^^^^^^^^^^^^^^^^^^^^^^^^^^^^
  File "C:\Users\ellie\OneDrive\Documents\Programming\Python\Level 6\Major Project\app\admin\routes.py", line 126, in edit_user
    return render_template("maintain_user.html", admin=admin)
           ^^^^^^^^^^^^^^^^^^^^^^^^^^^^^^^^^^^^^^^^^^^^^^^^^^
  File "c:\Users\ellie\OneDrive\Documents\Programming\Python\Level 6\Major Project\.venv\Lib\site-packages\flask\templating.py", line 150, in render_template
    return _render(app, template, context)
           ^^^^^^^^^^^^^^^^^^^^^^^^^^^^^^^
  File "c:\Users\ellie\OneDrive\Documents\Programming\Python\Level 6\Major Project\.venv\Lib\site-packages\flask\templating.py", line 131, in _render
    rv = template.render(context)
         ^^^^^^^^^^^^^^^^^^^^^^^^
  File "c:\Users\ellie\OneDrive\Documents\Programming\Python\Level 6\Major Project\.venv\Lib\site-packages\jinja2\environment.py", line 1301, in render
    self.environment.handle_exception()
  File "c:\Users\ellie\OneDrive\Documents\Programming\Python\Level 6\Major Project\.venv\Lib\site-packages\jinja2\environment.py", line 936, in handle_exception
    raise rewrite_traceback_stack(source=source)
  File "C:\Users\ellie\OneDrive\Documents\Programming\Python\Level 6\Major Project\app\admin\templates\maintain_user.html", line 1, in top-level template code
    {% extends "layout.html" %}
    ^^^^^^^^^^^^^^^^^^^^^^^^^
  File "C:\Users\ellie\OneDrive\Documents\Programming\Python\Level 6\Major Project\app\main\templates\layout.html", line 48, in top-level template code
    {% block content %}
  File "C:\Users\ellie\OneDrive\Documents\Programming\Python\Level 6\Major Project\app\admin\templates\maintain_user.html", line 19, in block 'content'
    {% for admin in admin %}
TypeError: 'User' object is not iterable
2024-04-21 18:18:25 - INFO - Username: admin logged in successfully
2024-04-21 18:18:33 - ERROR - Exception on /edit_user/1 [GET]
Traceback (most recent call last):
  File "c:\Users\ellie\OneDrive\Documents\Programming\Python\Level 6\Major Project\.venv\Lib\site-packages\flask\app.py", line 1463, in wsgi_app
    response = self.full_dispatch_request()
               ^^^^^^^^^^^^^^^^^^^^^^^^^^^^
  File "c:\Users\ellie\OneDrive\Documents\Programming\Python\Level 6\Major Project\.venv\Lib\site-packages\flask\app.py", line 872, in full_dispatch_request
    rv = self.handle_user_exception(e)
         ^^^^^^^^^^^^^^^^^^^^^^^^^^^^^
  File "c:\Users\ellie\OneDrive\Documents\Programming\Python\Level 6\Major Project\.venv\Lib\site-packages\flask\app.py", line 870, in full_dispatch_request
    rv = self.dispatch_request()
         ^^^^^^^^^^^^^^^^^^^^^^^
  File "c:\Users\ellie\OneDrive\Documents\Programming\Python\Level 6\Major Project\.venv\Lib\site-packages\flask\app.py", line 855, in dispatch_request
    return self.ensure_sync(self.view_functions[rule.endpoint])(**view_args)  # type: ignore[no-any-return]
           ^^^^^^^^^^^^^^^^^^^^^^^^^^^^^^^^^^^^^^^^^^^^^^^^^^^^^^^^^^^^^^^^^
  File "C:\Users\ellie\OneDrive\Documents\Programming\Python\Level 6\Major Project\app\admin\routes.py", line 126, in edit_user
    return render_template("maintain_user.html", admin=admin)
           ^^^^^^^^^^^^^^^^^^^^^^^^^^^^^^^^^^^^^^^^^^^^^^^^^^
  File "c:\Users\ellie\OneDrive\Documents\Programming\Python\Level 6\Major Project\.venv\Lib\site-packages\flask\templating.py", line 150, in render_template
    return _render(app, template, context)
           ^^^^^^^^^^^^^^^^^^^^^^^^^^^^^^^
  File "c:\Users\ellie\OneDrive\Documents\Programming\Python\Level 6\Major Project\.venv\Lib\site-packages\flask\templating.py", line 131, in _render
    rv = template.render(context)
         ^^^^^^^^^^^^^^^^^^^^^^^^
  File "c:\Users\ellie\OneDrive\Documents\Programming\Python\Level 6\Major Project\.venv\Lib\site-packages\jinja2\environment.py", line 1301, in render
    self.environment.handle_exception()
  File "c:\Users\ellie\OneDrive\Documents\Programming\Python\Level 6\Major Project\.venv\Lib\site-packages\jinja2\environment.py", line 936, in handle_exception
    raise rewrite_traceback_stack(source=source)
  File "C:\Users\ellie\OneDrive\Documents\Programming\Python\Level 6\Major Project\app\admin\templates\maintain_user.html", line 1, in top-level template code
    {% extends "layout.html" %}
    ^^^^^^^^^^^^^^^^^^^^^^^^^
  File "C:\Users\ellie\OneDrive\Documents\Programming\Python\Level 6\Major Project\app\main\templates\layout.html", line 48, in top-level template code
    {% block content %}
  File "C:\Users\ellie\OneDrive\Documents\Programming\Python\Level 6\Major Project\app\admin\templates\maintain_user.html", line 19, in block 'content'
    {% for admin in admin %}
TypeError: 'User' object is not iterable
2024-04-21 18:21:38 - INFO - Username: admin logged in successfully
2024-04-21 18:22:47 - INFO - Username: admin logged in successfully
2024-04-21 18:24:21 - ERROR - Exception on /register/ [POST]
Traceback (most recent call last):
  File "c:\Users\ellie\OneDrive\Documents\Programming\Python\Level 6\Major Project\.venv\Lib\site-packages\flask\app.py", line 1463, in wsgi_app
    response = self.full_dispatch_request()
               ^^^^^^^^^^^^^^^^^^^^^^^^^^^^
  File "c:\Users\ellie\OneDrive\Documents\Programming\Python\Level 6\Major Project\.venv\Lib\site-packages\flask\app.py", line 872, in full_dispatch_request
    rv = self.handle_user_exception(e)
         ^^^^^^^^^^^^^^^^^^^^^^^^^^^^^
  File "c:\Users\ellie\OneDrive\Documents\Programming\Python\Level 6\Major Project\.venv\Lib\site-packages\flask\app.py", line 870, in full_dispatch_request
    rv = self.dispatch_request()
         ^^^^^^^^^^^^^^^^^^^^^^^
  File "c:\Users\ellie\OneDrive\Documents\Programming\Python\Level 6\Major Project\.venv\Lib\site-packages\flask\app.py", line 855, in dispatch_request
    return self.ensure_sync(self.view_functions[rule.endpoint])(**view_args)  # type: ignore[no-any-return]
           ^^^^^^^^^^^^^^^^^^^^^^^^^^^^^^^^^^^^^^^^^^^^^^^^^^^^^^^^^^^^^^^^^
  File "C:\Users\ellie\OneDrive\Documents\Programming\Python\Level 6\Major Project\app\user\routes.py", line 78, in register
    new_user = User(username=form.username.data, branch_id = form.branch_id.data, password=hashed_password)
               ^^^^^^^^^^^^^^^^^^^^^^^^^^^^^^^^^^^^^^^^^^^^^^^^^^^^^^^^^^^^^^^^^^^^^^^^^^^^^^^^^^^^^^^^^^^^
  File "<string>", line 4, in __init__
  File "c:\Users\ellie\OneDrive\Documents\Programming\Python\Level 6\Major Project\.venv\Lib\site-packages\sqlalchemy\orm\state.py", line 564, in _initialize_instance
    with util.safe_reraise():
  File "c:\Users\ellie\OneDrive\Documents\Programming\Python\Level 6\Major Project\.venv\Lib\site-packages\sqlalchemy\util\langhelpers.py", line 146, in __exit__
    raise exc_value.with_traceback(exc_tb)
  File "c:\Users\ellie\OneDrive\Documents\Programming\Python\Level 6\Major Project\.venv\Lib\site-packages\sqlalchemy\orm\state.py", line 562, in _initialize_instance
    manager.original_init(*mixed[1:], **kwargs)
  File "c:\Users\ellie\OneDrive\Documents\Programming\Python\Level 6\Major Project\.venv\Lib\site-packages\sqlalchemy\orm\decl_base.py", line 2139, in _declarative_constructor
    raise TypeError(
TypeError: 'branch_id' is an invalid keyword argument for User
