2024-05-08 21:03:42 - ERROR - Exception on /manage_account [GET]
Traceback (most recent call last):
  File "c:\Users\ellie\OneDrive\Documents\Programming\Python\Level 6\Major Project\.venv\Lib\site-packages\flask\app.py", line 1463, in wsgi_app
    response = self.full_dispatch_request()
               ^^^^^^^^^^^^^^^^^^^^^^^^^^^^
  File "c:\Users\ellie\OneDrive\Documents\Programming\Python\Level 6\Major Project\.venv\Lib\site-packages\flask\app.py", line 872, in full_dispatch_request
    rv = self.handle_user_exception(e)
         ^^^^^^^^^^^^^^^^^^^^^^^^^^^^^
  File "c:\Users\ellie\OneDrive\Documents\Programming\Python\Level 6\Major Project\.venv\Lib\site-packages\flask\app.py", line 870, in full_dispatch_request
    rv = self.dispatch_request()
         ^^^^^^^^^^^^^^^^^^^^^^^
  File "c:\Users\ellie\OneDrive\Documents\Programming\Python\Level 6\Major Project\.venv\Lib\site-packages\flask\app.py", line 855, in dispatch_request
    return self.ensure_sync(self.view_functions[rule.endpoint])(**view_args)  # type: ignore[no-any-return]
           ^^^^^^^^^^^^^^^^^^^^^^^^^^^^^^^^^^^^^^^^^^^^^^^^^^^^^^^^^^^^^^^^^
  File "c:\Users\ellie\OneDrive\Documents\Programming\Python\Level 6\Major Project\.venv\Lib\site-packages\flask_login\utils.py", line 290, in decorated_view
    return current_app.ensure_sync(func)(*args, **kwargs)
           ^^^^^^^^^^^^^^^^^^^^^^^^^^^^^^^^^^^^^^^^^^^^^^
  File "C:\Users\ellie\OneDrive\Documents\Programming\Python\Level 6\Major Project\app\user\routes.py", line 119, in manage_account
    return render_template("manage_account.html", edit_account=edit_account)
           ^^^^^^^^^^^^^^^^^^^^^^^^^^^^^^^^^^^^^^^^^^^^^^^^^^^^^^^^^^^^^^^^^
  File "c:\Users\ellie\OneDrive\Documents\Programming\Python\Level 6\Major Project\.venv\Lib\site-packages\flask\templating.py", line 150, in render_template
    return _render(app, template, context)
           ^^^^^^^^^^^^^^^^^^^^^^^^^^^^^^^
  File "c:\Users\ellie\OneDrive\Documents\Programming\Python\Level 6\Major Project\.venv\Lib\site-packages\flask\templating.py", line 131, in _render
    rv = template.render(context)
         ^^^^^^^^^^^^^^^^^^^^^^^^
  File "c:\Users\ellie\OneDrive\Documents\Programming\Python\Level 6\Major Project\.venv\Lib\site-packages\jinja2\environment.py", line 1301, in render
    self.environment.handle_exception()
  File "c:\Users\ellie\OneDrive\Documents\Programming\Python\Level 6\Major Project\.venv\Lib\site-packages\jinja2\environment.py", line 936, in handle_exception
    raise rewrite_traceback_stack(source=source)
  File "C:\Users\ellie\OneDrive\Documents\Programming\Python\Level 6\Major Project\app\user\templates\manage_account.html", line 1, in top-level template code
    {% extends "layout.html" %}
    ^^^^^^^^^^^^^^^^^^^^^^^^^
  File "C:\Users\ellie\OneDrive\Documents\Programming\Python\Level 6\Major Project\app\main\templates\layout.html", line 55, in top-level template code
    {% block content %}
  File "C:\Users\ellie\OneDrive\Documents\Programming\Python\Level 6\Major Project\app\user\templates\manage_account.html", line 11, in block 'content'
    <input type='text' name='username' size="10" required class='form-control' value='{{edit_user.username}}' readonly>
    ^^^^^^^^^^^^^^^^^^^^^^^^^
  File "c:\Users\ellie\OneDrive\Documents\Programming\Python\Level 6\Major Project\.venv\Lib\site-packages\jinja2\environment.py", line 485, in getattr
    return getattr(obj, attribute)
           ^^^^^^^^^^^^^^^^^^^^^^^
jinja2.exceptions.UndefinedError: 'edit_user' is undefined
2024-05-08 21:04:40 - INFO - Username: admin logged in successfully
2024-05-08 21:04:48 - INFO - Username: admin accessed edit_account
2024-05-08 21:04:48 - ERROR - Exception on /manage_account [POST]
Traceback (most recent call last):
  File "c:\Users\ellie\OneDrive\Documents\Programming\Python\Level 6\Major Project\.venv\Lib\site-packages\flask\app.py", line 1463, in wsgi_app
    response = self.full_dispatch_request()
               ^^^^^^^^^^^^^^^^^^^^^^^^^^^^
  File "c:\Users\ellie\OneDrive\Documents\Programming\Python\Level 6\Major Project\.venv\Lib\site-packages\flask\app.py", line 872, in full_dispatch_request
    rv = self.handle_user_exception(e)
         ^^^^^^^^^^^^^^^^^^^^^^^^^^^^^
  File "c:\Users\ellie\OneDrive\Documents\Programming\Python\Level 6\Major Project\.venv\Lib\site-packages\flask\app.py", line 870, in full_dispatch_request
    rv = self.dispatch_request()
         ^^^^^^^^^^^^^^^^^^^^^^^
  File "c:\Users\ellie\OneDrive\Documents\Programming\Python\Level 6\Major Project\.venv\Lib\site-packages\flask\app.py", line 855, in dispatch_request
    return self.ensure_sync(self.view_functions[rule.endpoint])(**view_args)  # type: ignore[no-any-return]
           ^^^^^^^^^^^^^^^^^^^^^^^^^^^^^^^^^^^^^^^^^^^^^^^^^^^^^^^^^^^^^^^^^
  File "c:\Users\ellie\OneDrive\Documents\Programming\Python\Level 6\Major Project\.venv\Lib\site-packages\flask_login\utils.py", line 290, in decorated_view
    return current_app.ensure_sync(func)(*args, **kwargs)
           ^^^^^^^^^^^^^^^^^^^^^^^^^^^^^^^^^^^^^^^^^^^^^^
  File "C:\Users\ellie\OneDrive\Documents\Programming\Python\Level 6\Major Project\app\user\routes.py", line 106, in manage_account
    edit_account.branch_id = request.form['branch_id']
    ^^^^^^^^^^^^^^^^^^^^^^
AttributeError: 'list' object has no attribute 'branch_id'
2024-05-08 21:06:45 - INFO - Username: admin logged in successfully
2024-05-08 21:06:51 - INFO - Username: admin accessed edit_account
2024-05-08 21:06:52 - INFO - Username: admin successfully edited account admin
2024-05-08 21:11:16 - INFO - Username: admin logged in successfully
2024-05-08 21:11:25 - INFO - Username: admin accessed edit_account
2024-05-08 21:11:25 - INFO - Username: admin successfully edited account admin
2024-05-08 21:17:02 - INFO - Username: admin logged in successfully
2024-05-08 21:18:40 - INFO - Username: admin logged out
2024-05-08 21:18:50 - INFO - Username: admin logged in successfully
2024-05-26 16:34:57 - INFO - Username: admin logged in successfully
